Workbook

Sheet COMPANY
A1: COMPANY_NAME | B1: CATEGORY | C1: LOCATION | D1: FOUNDED_ON | E1: EXITED_ON | F1: CLOSED_ON | G1: REVENU_RANGE | H1: EMPLOYEE_NUMBER
A2: TangoMe | B2: Android, Apps, iOS, Messaging, Mobile | C2: Mountain View, California, United States | D2: Sep 9, 2009 | E2: — | F2: — | G2: $10M to $50M | H2: 101-250
A3: Zume Pizza | B3: Consumer, Food and Beverage, Food Delivery | C3: Mountain View, California, United States | D3: Sep 8, 2015 | E3: — | F3: Jan 2020 | G3: $50M to $100M | H3: 101-250
A4: LabCorp | B4: Biotechnology, Health Care, Hospital, Life Science, Medical | C4: Burlington, North Carolina, United States | D4: Sep 5, 1978 | E4: Jul 15, 1988 | F4: — | G4: $1B to $10B | H4: 10001+
A5: SoftBank | B5: Banking, Finance, Internet, Mobile, Telecommunications | C5: Tokyo, Tokyo, Japan | D5: Sep 3, 1981 | E5: May 14, 1999 | F5: — | G5: $10B+ | H5: 10001+
A6: Signal | B6: Analytics, Cloud Computing, Data Integration, Enterprise Software, Marketing, Marketing Automation, Project Management, SaaS | C6: Chicago, Illinois, United States | D6: Sep 26, 2009 | E6: Aug 17, 2020 | F6: — | G6: $10M to $50M | H6: 11-50
A7: DHL | B7: Logistics, Supply Chain Management | C7: Bonn, Nordrhein-Westfalen, Germany | D7: Sep 25, 1969 | E7: — | F7: — | G7: $50M to $100M | H7: 1-10
A8: Sprinklr | B8: Advertising Platforms, Analytics, Customer Service, Digital Marketing, Enterprise Software, Social CRM, Social Media, Social Media Advertising, Social Media Management, Software | C8: New York, New York, United States | D8: Sep 24, 2009 | E8: — | F8: — | G8: $100M to $500M | H8: 1001-5000
A9: KFC | B9: Food and Beverage, Restaurants, Retail | C9: Louisville, Kentucky, United States | D9: Sep 24, 1952 | E9: Jul 25, 1986 | F9: — | G9: $10B+ | H9: 10001+
A10: Confluent | B10: Analytics, Big Data, Cloud Data Services, Enterprise Software, Open Source, Software | C10: Mountain View, California, United States | D10: Sep 23, 2014 | E10: — | F10: — | G10: $10M to $50M | H10: 1001-5000
A11: Yandex | B11: Big Data, Developer Tools, Email, Information Technology, Mobile, Search Engine | C11: Moscow, Moscow City, Russian Federation | D11: Sep 23, 1997 | E11: May 24, 2011 | F11: — | G11: $500M to $1B | H11: 5001-10000
A12: ShearShare | B12: B2B, Beauty, Marketplace, Mobile, Mobile Apps, Sharing Economy | C12: Mckinney, Texas, United States | D12: Sep 2015 | E12: — | F12: — | G12: Less than $1M | H12: 11-50
... A1001: Schneider Electric | B1001: Electronics, Energy, Energy Management, Enterprise Software, Information Technology, Renewable Energy, Software | C1001: Rueil-malmaison, Ile-de-France, France | D1001: 1836 | E1001: — | F1001: — | G1001: $1B to $10B | H1001: 10001+

Sheet INVESTMENT
A1: COMPANY_NAME | B1: LOCATION | C1: FUNDING_TYPE | D1: MONEY_RAISED | E1: ANNOUNCED_DATE | F1: INVESTMENT_STAGE
A2: 1mg | B2: =_xlfn.XLOOKUP(INVESTMENT!A2475,COMPANY!A:A,COMPANY!C:C) -> San Francisco, California, United States | C2: Venture - Series Unknown | D2: ₹710,000,000 | E2: Jan 31, 2020 | F2: —
A3: 1mg | B3: =_xlfn.XLOOKUP(INVESTMENT!A252,COMPANY!A:A,COMPANY!C:C) -> Cyberport, Hong Kong Island, Hong Kong | C3: Series A | D3: $6,000,000 | E3: Apr 20, 2015 | F3: Early Stage Venture
A4: 1mg | B4: =_xlfn.XLOOKUP(INVESTMENT!A253,COMPANY!A:A,COMPANY!C:C) -> Cyberport, Hong Kong Island, Hong Kong | C4: Series A | D4: $6,000,000 | E4: Apr 20, 2015 | F4: Early Stage Venture
A5: 1mg | B5: =_xlfn.XLOOKUP(INVESTMENT!A2912,COMPANY!A:A,COMPANY!C:C) -> Chicago, Illinois, United States | C5: Debt Financing | D5: $17,800,000 | E5: Jul 3, 2020 | F5: —
A6: 1mg | B6: =_xlfn.XLOOKUP(INVESTMENT!A255,COMPANY!A:A,COMPANY!C:C) -> Cyberport, Hong Kong Island, Hong Kong | C6: Series B | D6: $16,000,000 | E6: Apr 20, 2016 | F6: Early Stage Venture
A7: 1mg | B7: =_xlfn.XLOOKUP(INVESTMENT!A40,COMPANY!A:A,COMPANY!C:C) -> London, England, United Kingdom | C7: Series B | D7: $13,800,000 | E7: Apr 1, 2016 | F7: Early Stage Venture
A8: 1mg | B8: =_xlfn.XLOOKUP(INVESTMENT!A222,COMPANY!A:A,COMPANY!C:C) -> San Francisco, California, United States | C8: Debt Financing | D8: $13,300,000 | E8: Apr 19, 2021 | F8: —
A9: 1mg | B9: =_xlfn.XLOOKUP(INVESTMENT!A2600,COMPANY!A:A,COMPANY!C:C) -> San Francisco, California, United States | C9: Series C | D9: $12,200,000 | E9: Jul 1, 2017 | F9: Late Stage Venture
A10: 1mg | B10: =_xlfn.XLOOKUP(INVESTMENT!A4406,COMPANY!A:A,COMPANY!C:C) -> Austin, Texas, United States | C10: Venture - Series Unknown | D10: — | E10: May 31, 2016 | F10: —
A11: 1mg | B11: =_xlfn.XLOOKUP(INVESTMENT!A4407,COMPANY!A:A,COMPANY!C:C) -> Shanghai, Shanghai, China | C11: Venture - Series Unknown | D11: — | E11: May 31, 2016 | F11: —
A12: 23andMe | B12: =_xlfn.XLOOKUP(INVESTMENT!A1424,COMPANY!A:A,COMPANY!C:C) -> London, England, United Kingdom | C12: Series F | D12: $82,500,000 | E12: Dec 29, 2020 | F12: Late Stage Venture
A13: 23andMe | B13: =_xlfn.XLOOKUP(INVESTMENT!A5286,COMPANY!A:A,COMPANY!C:C) -> San Francisco, California, United States | C13: Series A | D13: $8,953,320 | E13: Oct 3, 2007 | F13: Early Stage Venture
A14: 23andMe | B14: =_xlfn.XLOOKUP(INVESTMENT!A1353,COMPANY!A:A,COMPANY!C:C) -> London, England, United Kingdom | C14: Series D | D14: $50,000,000 | E14: Dec 21, 2012 | F14: Late Stage Venture
A15: 23andMe | B15: =_xlfn.XLOOKUP(INVESTMENT!A1354,COMPANY!A:A,COMPANY!C:C) -> London, England, United Kingdom | C15: Series D | D15: $50,000,000 | E15: Dec 21, 2012 | F15: Late Stage Venture
A16: 23andMe | B16: =_xlfn.XLOOKUP(INVESTMENT!A1355,COMPANY!A:A,COMPANY!C:C) -> London, England, United Kingdom | C16: Series D | D16: $50,000,000 | E16: Dec 21, 2012 | F16: Late Stage Venture
A17: 23andMe | B17: =_xlfn.XLOOKUP(INVESTMENT!A2834,COMPANY!A:A,COMPANY!C:C) -> New York, New York, United States | C17: Corporate Round | D17: $300,000,000 | E17: Jul 24, 2018 | F17: —
A18: 23andMe | B18: =_xlfn.XLOOKUP(INVESTMENT!A5867,COMPANY!A:A,COMPANY!C:C) -> Brooklyn, New York, United States | C18: Series F | D18: $250,000,000 | E18: Sep 5, 2017 | F18: Late Stage Venture
A19: 23andMe | B19: =_xlfn.XLOOKUP(INVESTMENT!A1388,COMPANY!A:A,COMPANY!C:C) -> San Francisco, California, United States | C19: Series B | D19: $14,200,000 | E19: Dec 23, 2009 | F19: Early Stage Venture
A20: 23andMe | B20: =_xlfn.XLOOKUP(INVESTMENT!A1389,COMPANY!A:A,COMPANY!C:C) -> San Francisco, California, United States | C20: Series B | D20: $14,200,000 | E20: Dec 23, 2009 | F20: Early Stage Venture
A21: 23andMe | B21: =_xlfn.XLOOKUP(INVESTMENT!A4945,COMPANY!A:A,COMPANY!C:C) -> San Francisco, California, United States | C21: Debt Financing | D21: — | E21: Nov 8, 2010 | F21: —
A22: 23andMe | B22: =_xlfn.XLOOKUP(INVESTMENT!A5198,COMPANY!A:A,COMPANY!C:C) -> Boston, Massachusetts, United States | C22: Series F | D22: — | E22: Oct 23, 2018 | F22: Late Stage Venture
A23: 360VUZ | B23: =_xlfn.XLOOKUP(INVESTMENT!A262,COMPANY!A:A,COMPANY!C:C) -> Cyberport, Hong Kong Island, Hong Kong | C23: Series A | D23: $7,093,000 | E23: Apr 20, 2020 | F23: Early Stage Venture
A24: 360VUZ | B24: =_xlfn.XLOOKUP(INVESTMENT!A1454,COMPANY!A:A,COMPANY!C:C) -> Burlington, Massachusetts, United States | C24: Seed | D24: $1,350,000 | E24: Dec 30, 2017 | F24: Seed
A25: 360VUZ | B25: =_xlfn.XLOOKUP(INVESTMENT!A2340,COMPANY!A:A,COMPANY!C:C) -> Mountain View, California, United States | C25: Seed | D25: — | E25: Jan 22, 2019 | F25: Seed
A26: 4D Molecular Therapeutics | B26: =_xlfn.XLOOKUP(INVESTMENT!A5871,COMPANY!A:A,COMPANY!C:C) -> Gurgaon, Haryana, India | C26: Series B | D26: $90,000,000 | E26: Sep 5, 2018 | F26: Early Stage Venture
A27: 4D Molecular Therapeutics | B27: =_xlfn.XLOOKUP(INVESTMENT!A3170,COMPANY!A:A,COMPANY!C:C) -> New York, New York, United States | C27: Series C | D27: $75,000,000 | E27: Jun 16, 2020 | F27: Late Stage Venture
A28: 4D Molecular Therapeutics | B28: =_xlfn.XLOOKUP(INVESTMENT!A633,COMPANY!A:A,COMPANY!C:C) -> Berkeley, California, United States | C28: Venture - Series Unknown | D28: $6,999,995 | E28: Aug 13, 2015 | F28: —
A29: 908 Devices | B29: =_xlfn.XLOOKUP(INVESTMENT!A840,COMPANY!A:A,COMPANY!C:C) -> New York, New York, United States | C29: Series B | D29: $7,000,000 | E29: Aug 27, 2013 | F29: Early Stage Venture
A30: 908 Devices | B30: =_xlfn.XLOOKUP(INVESTMENT!A841,COMPANY!A:A,COMPANY!C:C) -> New York, New York, United States | C30: Series B | D30: $7,000,000 | E30: Aug 27, 2013 | F30: Early Stage Venture
A31: 908 Devices | B31: =_xlfn.XLOOKUP(INVESTMENT!A3610,COMPANY!A:A,COMPANY!C:C) -> Seattle, Washington, United States | C31: Series D | D31: $20,000,000 | E31: Mar 15, 2017 | F31: Late Stage Venture
A32: 908 Devices | B32: =_xlfn.XLOOKUP(INVESTMENT!A3611,COMPANY!A:A,COMPANY!C:C) -> Seattle, Washington, United States | C32: Series D | D32: $20,000,000 | E32: Mar 15, 2017 | F32: Late Stage Venture
A33: 908 Devices | B33: =_xlfn.XLOOKUP(INVESTMENT!A398,COMPANY!A:A,COMPANY!C:C) -> San Francisco, California, United States | C33: Series E | D33: $17,500,000 | E33: Apr 29, 2019 | F33: Late Stage Venture
A34: 908 Devices | B34: =_xlfn.XLOOKUP(INVESTMENT!A4464,COMPANY!A:A,COMPANY!C:C) -> New York, New York, United States | C34: Series C | D34: $11,600,000 | E34: May 6, 2015 | F34: Late Stage Venture
A35: 908 Devices | B35: =_xlfn.XLOOKUP(INVESTMENT!A3609,COMPANY!A:A,COMPANY!C:C) -> Seattle, Washington, United States | C35: Debt Financing | D35: — | E35: Mar 15, 2017 | F35: —
A36: Aave | B36: =_xlfn.XLOOKUP(INVESTMENT!A3001,COMPANY!A:A,COMPANY!C:C) -> Burlingame, California, United States | C36: Initial Coin Offering | D36: $4,500,000 | E36: Jul 8, 2020 | F36: —
A37: Aave | B37: =_xlfn.XLOOKUP(INVESTMENT!A2702,COMPANY!A:A,COMPANY!C:C) -> Louisville, Kentucky, United States | C37: Initial Coin Offering | D37: $3,000,000 | E37: Jul 15, 2020 | F37: —
A38: Aave | B38: =_xlfn.XLOOKUP(INVESTMENT!A5070,COMPANY!A:A,COMPANY!C:C) -> San Francisco, California, United States | C38: Venture - Series Unknown | D38: $25,000,000 | E38: Oct 12, 2020 | F38: —
A39: Aave | B39: =_xlfn.XLOOKUP(INVESTMENT!A4837,COMPANY!A:A,COMPANY!C:C) -> New York, New York, United States | C39: Initial Coin Offering | D39: $16,500,000 | E39: Nov 25, 2017 | F39: —
A40: Aave | B40: =_xlfn.XLOOKUP(INVESTMENT!A2461,COMPANY!A:A,COMPANY!C:C) -> Seattle, Washington, United States | C40: Secondary Market | D40: — | E40: Jan 30, 2021 | F40: —
...

Sheet ACQUISITION
A1: COMPANY_NAME | B1: ACQUIREE_NAME | C1: ANNOUNCED_DATE | D1: PRICE | E1: ACQUISITION_TYPE
A2: 1mg | B2: Dawailelo | C2: Sep 1, 2017 | D2: — | E2: Acquisition
A3: 1mg | B3: Medd.in | C3: Jul 5, 2016 | D3: — | E3: Acquisition
A4: 23andMe | B4: Virgin Group | C4: Feb 5, 2021 | D4: — | E4: Merger
A5: 23andMe | B5: CureTogether | C5: Jul 10, 2012 | D5: — | E5: —
A6: AbCellera Biologics | B6: Dualogics - OrthoMab | C6: Aug 20, 2020 | D6: — | E6: Acquisition
A7: AbCellera Biologics | B7: Trianni | C7: Nov 18, 2020 | D7: $90,000,000 | E7: Acquisition
A8: AbCellera Biologics | B8: Lineage Biosciences | C8: Aug 1, 2018 | D8: — | E8: Acquisition
A9: Accenture | B9: AppsPro | C9: May 3, 2021 | D9: — | E9: Acquisition
A10: Accenture | B10: AppsPro | C10: May 3, 2021 | D10: — | E10: Acquisition
A11: Accenture | B11: BUSINET SYSTEM | C11: Feb 1, 2021 | D11: — | E11: Acquisition
A12: Accenture | B12: Cirrus | C12: Mar 1, 2021 | D12: — | E12: Acquisition
... A5290: Zuora | B5290: Frontleaf | C5290: May 20, 2015 | D5290: — | E5290: Acquisition

Sheet EMPLOYEE
A1: EMPLOYEE_MD5 | B1: JOB_TITLES | C1: COMPANY_NAME | D1: ATTENDED_SCHOOLS
A2: 1360e802a0514901cfe81e905d533168 | B2: Chief Operating Officer | C2: 1mg
A3: 4a7e3c46f6f02bc649adf89d8af78590 | B3: Co-Founder and CEO | C3: 1mg | D3: Harvard Business School Indian Institute of Technology Delhi
A4: 4e465c8ae639d50a866c7ba6aa584e82 | B4: CEO & Co-Founder | C4: 1mg | D4: Indian Institute of Technology Delhi Stanford University
A5: 6910ff251504d8ed442de572a92d2ec1 | B5: Co-Founder | C5: 1mg
A6: a0ca5d14863b0a86ff79e2fef87cc89e | B6: Business Development & Marketing Manager | C6: 1mg | D6: Shri Ramdeobaba College of Engineering and Management
A7: d93ed2e1cef9b1a647afcc7ce5f55170 | B7: Senior UX Designer | C7: 1mg | D7: Indian Institute of Technology Kanpur
A8: dc43866eddb6a7dc5384d72b84b341d3 | B8: Consultant | C8: 1mg | D8: Dr. K.N.Modi institute of Engineering & Technology
A9: 0a474afac723e6fb2f00032bae24601d | B9: Privacy and Data Protection Counsel | C9: 23andMe
A10: 0f1fad3a7abc3187fed777b99d3daff3 | B10: Chief Legal and Regulatory Officer | C10: 23andMe | D10: University of California Hastings College of Law
A11: 1df0182bd95ab262d23ffdc194c5f882 | B11: Vice President, Computational Biology | C11: 23andMe
A12: 38bc7b30fdb653fa36eb488df9272620 | B12: Senior Scientist Statistical Genetics, Health R+D | C12: 23andMe | D12: The University of Memphis University of California, Los Angeles (UCLA)
A13: 6e42990ec9f13f9e1662998ab9842cd5 | B13: Director & Research Infrastructure | C13: 23andMe
A14: 73c5e9448c15434cae2661b4f610e97c | B14: Chief Science Officer and Head of Therapeutics | C14: 23andMe | D14: Caltech - California Institute of Technology University of Wisconsin - Madison
A15: 9485c49e6bb738b8eba417fa8a19bb54 | B15: Co-Founder and CEO | C15: 23andMe | D15: Yale University
A16: c89d9316ccfee139692d1f6945be2bf7 | B16: Vice President, Research | C16: 23andMe | D16: Stanford University University of California, San Francisco
A17: a50c46df4404d961976a414997746f68 | B17: Co-Founder | C17: 360VUZ
A18: 1d4d8f0246772206796b8e54862c5e0c | B18: Co-Founder, President & CEO | C18: 4D Molecular Therapeutics
A19: 17e4e3de2309e367b717970614d7cd92 | B19: Co-Founder | C19: 908 Devices | D19: University of Strathclyde
A20: 18355614c3653f42ba6deef5472f0c77 | B20: Science Founder | C20: 908 Devices | D20: Indiana University
A21: 26aa094998990d8b644eef80fea4418a | B21: VP of Sales | C21: 908 Devices
A22: 3da6864541a01e9e1990fd9270f20743 | B22: Co-founder & CEO | C22: 908 Devices | D22: University of Colorado
A23: 45c40d841cbe0553f65388fd9426385c | B23: Co-Founder and VP of Business Development and Marketing | C23: 908 Devices
A24: 511bd8429159f3385d4e40c4775d3f0e | B24: Co-Founder | C24: 908 Devices
A25: 98e25847ac411c1b50475be7c1ab1f90 | B25: Co-Founder | C25: 908 Devices
A26: b7af8dbf5d00e4202de0739b2ce87974 | B26: Co-Founder | C26: 908 Devices
A27: d83fface22f39a038d46ddc048e25822 | B27: Co-Founder | C27: 908 Devices
A28: f1403614138d085b5f55dc1c8a5a2497 | B28: Co-Founder & CTO | C28: 908 Devices | D28: Brandon University Dalhousie University
A29: 768305055b03932f4ffe14d676aa4058 | B29: User Success Manager | C29: Aave
A30: 8fbb11d09f061fb0866976a942ca5f37 | B30: CEO & Founder | C30: Aave
A31: a0048e0cbf4d417f4dfa8110c9959f6f | B31: CEO | C31: AbCellera Biologics
A32: a158da117d28703cd242fb7bea7e7ac5 | B32: Co-Founder & Director | C32: AbCellera Biologics
A33: f00d00b8ae73e22f72cc573776f4705e | B33: Co-Founder | C33: AbCellera Biologics | D33: Claude Bernard University Lyon 1
A34: 9360e358428e7fff731e98119b5715b4 | B34: Vice President of Marketing | C34: Abnormal Security
A35: 9a2eabbd36ca3c9ea611a5a368aee045 | B35: CEO & Co-founder | C35: Abnormal Security
A36: bea99e96a8a994abdb44bdc404135810 | B36: Head of Engineering | C36: Abnormal Security
A37: f075c4b87899cd89a505452ed7016873 | B37: Region Manager - Enterprise Sales | C37: Abnormal Security
A38: f8226dd2f110443f9c5e4d3f1e321e02 | B38: CTO & Co-Founder | C38: Abnormal Security
A39: 0057e240c373870fbbd99210abaab372 | B39: Managing Director | C39: Accenture
A40: 00bab153925406e4905fb24b235205ac | B40: Manager for Accenture Information Management Services | C40: Accenture
...

Sheet Continents
A1: Country | B1: Continent
A2: Afghanistan | B2: Asia
A3: Albania | B3: Europe
A4: Algeria | B4: Africa
A5: American Samoa | B5: Oceania
A6: Andorra | B6: Europe
A7: Angola | B7: Africa
A8: Anguilla | B8: North America
A9: Antigua and Barbuda | B9: North America
A10: Argentina | B10: South America
A11: Armenia | B11: Asia
A12: Aruba | B12: North America
... A235: Zimbabwe | B235: Africa
